

https://github.com/kubernetes-client/python/issues/521


this problem caused by urllib3 with ssl,
modify python3.6/site-packages/kubernetes/client/configuration.py:
self.verify_ssl = True ---> False

vi  /usr/lib/python2.7/site-packages/kubernetes/client/configuration.py